Workbook

Sheet 월 비교
C1: 3 | V1: 원가율
G2: 전전월 대비 전월 | I2: 전월 대비 당월 | Q2: 전전월 대비 전월 | S2: 전월 대비 당월 | V2: 전전월 | W2: 전월 | X2: 당월
B3: 연결계정 | C3: 연결계정명 | D3: 전전월(A) | E3: 전월(B) | F3: 당월(C) | G3: 증감(B-A) | H3: % | I3: 증감(C-B) | J3: % | L3: 연결계정 | M3: 연결계정명 | N3: 전전월 | O3: 전월 | P3: 당월 | Q3: 증감(B-A) | R3: % | S3: 증감(C-B) | T3: % | V3: =N21/N4 -> 0.75090078 | W3: =O21/O4 -> 0.68399767 | X3: =P21/P4 -> 0.7799416
B4: FP01 | C4: 자산 | D4: =VLOOKUP(B4,BS!$A:$S,18,FALSE)-VLOOKUP(B4,BS!$A:$S,$C$1+5,FALSE)-VLOOKUP(B4,BS!$A:$S,$C$1+4,FALSE) -> 2.6357673e+09 | E4: =VLOOKUP(B4,BS!$A:$S,18,FALSE)-VLOOKUP(B4,BS!$A:$S,$C$1+5,FALSE) -> 2.5926516e+09 | F4: =VLOOKUP(B4,BS!$A:$S,18,FALSE) -> 2.4941833e+09 | G4: =E4-D4 -> -43115788 | H4: =IFERROR(G4/D4,0) -> -0.016357964 | I4: =F4-E4 -> -98468299 | J4: =IFERROR(I4/E4,0) -> -0.037979766 | L4: PL01 | M4: 매출액 | N4: =VLOOKUP(L4,PL!$A:$S,$C$1+3,FALSE) -> 2.3546103e+08 | O4: =VLOOKUP(L4,PL!$A:$S,$C$1+4,FALSE) -> 1.4588191e+08 | P4: =VLOOKUP(L4,PL!$A:$S,$C$1+5,FALSE) -> 1.5976989e+08 | Q4: =O4-N4 -> -89579125 | R4: =IFERROR(Q4/N4,0) -> -0.3804414 | S4: =P4-O4 -> 13887985 | T4: =IFERROR(S4/O4,0) -> 0.095200188
B5: FP01-01 | C5: 유동자산 | D5: =VLOOKUP(B5,BS!$A:$S,18,FALSE)-VLOOKUP(B5,BS!$A:$S,$C$1+5,FALSE)-VLOOKUP(B5,BS!$A:$S,$C$1+4,FALSE) -> 2.4124284e+09 | E5: =VLOOKUP(B5,BS!$A:$S,18,FALSE)-VLOOKUP(B5,BS!$A:$S,$C$1+5,FALSE) -> 2.3738052e+09 | F5: =VLOOKUP(B5,BS!$A:$S,18,FALSE) -> 2.2830502e+09 | G5: =E5-D5 -> -38623233 | H5: =IFERROR(G5/D5,0) -> -0.016010105 | I5: =F5-E5 -> -90755000 | J5: =IFERROR(I5/E5,0) -> -0.038231865 | L5: PL01-01 | M5: 상품매출액 | N5: =VLOOKUP(L5,PL!$A:$S,$C$1+3,FALSE) -> 2.3546103e+08 | O5: =VLOOKUP(L5,PL!$A:$S,$C$1+4,FALSE) -> 1.4588191e+08 | P5: =VLOOKUP(L5,PL!$A:$S,$C$1+5,FALSE) -> 1.5751817e+08 | Q5: =O5-N5 -> -89579120 | R5: =IFERROR(Q5/N5,0) -> -0.38044139 | S5: =P5-O5 -> 11636261 | T5: =IFERROR(S5/O5,0) -> 0.079764935 | V5: 유동비율
B6: FP01-01-01 | C6: 당좌자산 | D6: =VLOOKUP(B6,BS!$A:$S,18,FALSE)-VLOOKUP(B6,BS!$A:$S,$C$1+5,FALSE)-VLOOKUP(B6,BS!$A:$S,$C$1+4,FALSE) -> 1.4189341e+09 | E6: =VLOOKUP(B6,BS!$A:$S,18,FALSE)-VLOOKUP(B6,BS!$A:$S,$C$1+5,FALSE) -> 1.2800974e+09 | F6: =VLOOKUP(B6,BS!$A:$S,18,FALSE) -> 1.1737925e+09 | G6: =E6-D6 -> -1.3883664e+08 | H6: =IFERROR(G6/D6,0) -> -0.097845728 | I6: =F6-E6 -> -1.0630491e+08 | J6: =IFERROR(I6/E6,0) -> -0.083044389 | L6: PL01-01-0010 | M6: 본사상품매출액 | N6: =VLOOKUP(L6,PL!$A:$S,$C$1+3,FALSE) -> 11939353 | O6: =VLOOKUP(L6,PL!$A:$S,$C$1+4,FALSE) -> 24790709 | P6: =VLOOKUP(L6,PL!$A:$S,$C$1+5,FALSE) -> 8298747.6 | Q6: =O6-N6 -> 12851355 | R6: =IFERROR(Q6/N6,0) -> 1.0763862 | S6: =P6-O6 -> -16491961 | T6: =IFERROR(S6/O6,0) -> -0.66524767 | V6: 전전월 | W6: 전월 | X6: 당월
B7: FP01-01-01-0010 | C7: 현금및현금성자산 | D7: =VLOOKUP(B7,BS!$A:$S,18,FALSE)-VLOOKUP(B7,BS!$A:$S,$C$1+5,FALSE)-VLOOKUP(B7,BS!$A:$S,$C$1+4,FALSE) -> 5.9504378e+08 | E7: =VLOOKUP(B7,BS!$A:$S,18,FALSE)-VLOOKUP(B7,BS!$A:$S,$C$1+5,FALSE) -> 5.4573993e+08 | F7: =VLOOKUP(B7,BS!$A:$S,18,FALSE) -> 4.7915504e+08 | G7: =E7-D7 -> -49303850 | H7: =IFERROR(G7/D7,0) -> -0.082857517 | I7: =F7-E7 -> -66584889 | J7: =IFERROR(I7/E7,0) -> -0.12200846 | L7: PL01-01-0020 | M7: 본사제품매출액 | N7: =VLOOKUP(L7,PL!$A:$S,$C$1+3,FALSE) -> 2.1392202e+08 | O7: =VLOOKUP(L7,PL!$A:$S,$C$1+4,FALSE) -> 1.1373953e+08 | P7: =VLOOKUP(L7,PL!$A:$S,$C$1+5,FALSE) -> 1.4520763e+08 | Q7: =O7-N7 -> -1.0018249e+08 | R7: =IFERROR(Q7/N7,0) -> -0.46831312 | S7: =P7-O7 -> 31468097 | T7: =IFERROR(S7/O7,0) -> 0.27666808 | V7: =D5/D114 -> 0.65483875 | W7: =E5/E114 -> 0.63399248 | X7: =F5/F114 -> 0.63036042
B8: FP01-01-01-0020 | C8: 국고보조금(현금) | D8: =VLOOKUP(B8,BS!$A:$S,18,FALSE)-VLOOKUP(B8,BS!$A:$S,$C$1+5,FALSE)-VLOOKUP(B8,BS!$A:$S,$C$1+4,FALSE) -> 0 | E8: =VLOOKUP(B8,BS!$A:$S,18,FALSE)-VLOOKUP(B8,BS!$A:$S,$C$1+5,FALSE) -> 0 | F8: =VLOOKUP(B8,BS!$A:$S,18,FALSE) -> 0 | G8: =E8-D8 -> 0 | H8: =IFERROR(G8/D8,0) -> 0 | I8: =F8-E8 -> 0 | J8: =IFERROR(I8/E8,0) -> 0 | L8: PL01-01-0030 | M8: 미국제품매출액 | N8: =VLOOKUP(L8,PL!$A:$S,$C$1+3,FALSE) -> 5607110.5 | O8: =VLOOKUP(L8,PL!$A:$S,$C$1+4,FALSE) -> 5925504 | P8: =VLOOKUP(L8,PL!$A:$S,$C$1+5,FALSE) -> 3059391.2 | Q8: =O8-N8 -> 318393.58 | R8: =IFERROR(Q8/N8,0) -> 0.056783896 | S8: =P8-O8 -> -2866112.9 | T8: =IFERROR(S8/O8,0) -> -0.48369098
B9: FP01-01-01-0030 | C9: 단기금융상품 | D9: =VLOOKUP(B9,BS!$A:$S,18,FALSE)-VLOOKUP(B9,BS!$A:$S,$C$1+5,FALSE)-VLOOKUP(B9,BS!$A:$S,$C$1+4,FALSE) -> 0 | E9: =VLOOKUP(B9,BS!$A:$S,18,FALSE)-VLOOKUP(B9,BS!$A:$S,$C$1+5,FALSE) -> 0 | F9: =VLOOKUP(B9,BS!$A:$S,18,FALSE) -> 0 | G9: =E9-D9 -> 0 | H9: =IFERROR(G9/D9,0) -> 0 | I9: =F9-E9 -> 0 | J9: =IFERROR(I9/E9,0) -> 0 | L9: PL01-01-0040 | M9: 현지매입상품매출액 | N9: =VLOOKUP(L9,PL!$A:$S,$C$1+3,FALSE) -> 3992544.8 | O9: =VLOOKUP(L9,PL!$A:$S,$C$1+4,FALSE) -> 1426163.7 | P9: =VLOOKUP(L9,PL!$A:$S,$C$1+5,FALSE) -> 952401.85 | Q9: =O9-N9 -> -2566381 | R9: =IFERROR(Q9/N9,0) -> -0.64279331 | S9: =P9-O9 -> -473761.86 | T9: =IFERROR(S9/O9,0) -> -0.33219318 | V9: 부채비율
B10: FP01-01-01-0040 | C10: 단기매매증권 | D10: =VLOOKUP(B10,BS!$A:$S,18,FALSE)-VLOOKUP(B10,BS!$A:$S,$C$1+5,FALSE)-VLOOKUP(B10,BS!$A:$S,$C$1+4,FALSE) -> 0 | E10: =VLOOKUP(B10,BS!$A:$S,18,FALSE)-VLOOKUP(B10,BS!$A:$S,$C$1+5,FALSE) -> 0 | F10: =VLOOKUP(B10,BS!$A:$S,18,FALSE) -> 0 | G10: =E10-D10 -> 0 | H10: =IFERROR(G10/D10,0) -> 0 | I10: =F10-E10 -> 0 | J10: =IFERROR(I10/E10,0) -> 0 | L10: PL01-01-0050 | M10: 기타관계사제품매출액 | N10: =VLOOKUP(L10,PL!$A:$S,$C$1+3,FALSE) -> 0 | O10: =VLOOKUP(L10,PL!$A:$S,$C$1+4,FALSE) -> 0 | P10: =VLOOKUP(L10,PL!$A:$S,$C$1+5,FALSE) -> 0 | Q10: =O10-N10 -> 0 | R10: =IFERROR(Q10/N10,0) -> 0 | S10: =P10-O10 -> 0 | T10: =IFERROR(S10/O10,0) -> 0 | V10: 전전월 | W10: 전월 | X10: 당월
B11: FP01-01-01-0050 | C11: 만기보유증권 | D11: =VLOOKUP(B11,BS!$A:$S,18,FALSE)-VLOOKUP(B11,BS!$A:$S,$C$1+5,FALSE)-VLOOKUP(B11,BS!$A:$S,$C$1+4,FALSE) -> 0 | E11: =VLOOKUP(B11,BS!$A:$S,18,FALSE)-VLOOKUP(B11,BS!$A:$S,$C$1+5,FALSE) -> 0 | F11: =VLOOKUP(B11,BS!$A:$S,18,FALSE) -> 0 | G11: =E11-D11 -> 0 | H11: =IFERROR(G11/D11,0) -> 0 | I11: =F11-E11 -> 0 | J11: =IFERROR(I11/E11,0) -> 0 | L11: PL01-02 | M11: 제품매출액 | N11: =VLOOKUP(L11,PL!$A:$S,$C$1+3,FALSE) -> 0 | O11: =VLOOKUP(L11,PL!$A:$S,$C$1+4,FALSE) -> 0 | P11: =VLOOKUP(L11,PL!$A:$S,$C$1+5,FALSE) -> 0 | Q11: =O11-N11 -> 0 | R11: =IFERROR(Q11/N11,0) -> 0 | S11: =P11-O11 -> 0 | T11: =IFERROR(S11/O11,0) -> 0 | V11: =D113/D162 -> -3.5144779 | W11: =E113/E162 -> -3.2514156 | X11: =F113/F162 -> -3.2118733
B12: FP01-01-01-0060 | C12: 매도가능증권 | D12: =VLOOKUP(B12,BS!$A:$S,18,FALSE)-VLOOKUP(B12,BS!$A:$S,$C$1+5,FALSE)-VLOOKUP(B12,BS!$A:$S,$C$1+4,FALSE) -> 0 | E12: =VLOOKUP(B12,BS!$A:$S,18,FALSE)-VLOOKUP(B12,BS!$A:$S,$C$1+5,FALSE) -> 0 | F12: =VLOOKUP(B12,BS!$A:$S,18,FALSE) -> 0 | G12: =E12-D12 -> 0 | H12: =IFERROR(G12/D12,0) -> 0 | I12: =F12-E12 -> 0 | J12: =IFERROR(I12/E12,0) -> 0 | L12: PL01-03 | M12: 반제품매출액 | N12: =VLOOKUP(L12,PL!$A:$S,$C$1+3,FALSE) -> 0 | O12: =VLOOKUP(L12,PL!$A:$S,$C$1+4,FALSE) -> 0 | P12: =VLOOKUP(L12,PL!$A:$S,$C$1+5,FALSE) -> 0 | Q12: =O12-N12 -> 0 | R12: =IFERROR(Q12/N12,0) -> 0 | S12: =P12-O12 -> 0 | T12: =IFERROR(S12/O12,0) -> 0
B13: FP01-01-01-0070 | C13: 매출채권 | D13: =VLOOKUP(B13,BS!$A:$S,18,FALSE)-VLOOKUP(B13,BS!$A:$S,$C$1+5,FALSE)-VLOOKUP(B13,BS!$A:$S,$C$1+4,FALSE) -> 6.6121135e+08 | E13: =VLOOKUP(B13,BS!$A:$S,18,FALSE)-VLOOKUP(B13,BS!$A:$S,$C$1+5,FALSE) -> 6.0925313e+08 | F13: =VLOOKUP(B13,BS!$A:$S,18,FALSE) -> 5.6025549e+08 | G13: =E13-D13 -> -51958222 | H13: =IFERROR(G13/D13,0) -> -0.078580354 | I13: =F13-E13 -> -48997643 | J13: =IFERROR(I13/E13,0) -> -0.080422472 | L13: PL01-04 | M13: 원재료매출액 | N13: =VLOOKUP(L13,PL!$A:$S,$C$1+3,FALSE) -> 0 | O13: =VLOOKUP(L13,PL!$A:$S,$C$1+4,FALSE) -> 0 | P13: =VLOOKUP(L13,PL!$A:$S,$C$1+5,FALSE) -> 0 | Q13: =O13-N13 -> 0 | R13: =IFERROR(Q13/N13,0) -> 0 | S13: =P13-O13 -> 0 | T13: =IFERROR(S13/O13,0) -> 0 | V13: 영업이익율
B14: FP01-01-01-0080 | C14: 대손충당금(매출채권) | D14: =VLOOKUP(B14,BS!$A:$S,18,FALSE)-VLOOKUP(B14,BS!$A:$S,$C$1+5,FALSE)-VLOOKUP(B14,BS!$A:$S,$C$1+4,FALSE) -> -2.1881797e+08 | E14: =VLOOKUP(B14,BS!$A:$S,18,FALSE)-VLOOKUP(B14,BS!$A:$S,$C$1+5,FALSE) -> -2.8152365e+08 | F14: =VLOOKUP(B14,BS!$A:$S,18,FALSE) -> -2.7019784e+08 | G14: =E14-D14 -> -62705671 | H14: =IFERROR(G14/D14,0) -> 0.28656545 | I14: =F14-E14 -> 11325801 | J14: =IFERROR(I14/E14,0) -> -0.040230373 | L14: PL01-05 | M14: IT매출액 | N14: =VLOOKUP(L14,PL!$A:$S,$C$1+3,FALSE) -> 0 | O14: =VLOOKUP(L14,PL!$A:$S,$C$1+4,FALSE) -> 0 | P14: =VLOOKUP(L14,PL!$A:$S,$C$1+5,FALSE) -> 0 | Q14: =O14-N14 -> 0 | R14: =IFERROR(Q14/N14,0) -> 0 | S14: =P14-O14 -> 0 | T14: =IFERROR(S14/O14,0) -> 0 | V14: 전전월 | W14: 전월 | X14: 당월
B15: FP01-01-01-0090 | C15: 현재가치할인차금(단기) | D15: =VLOOKUP(B15,BS!$A:$S,18,FALSE)-VLOOKUP(B15,BS!$A:$S,$C$1+5,FALSE)-VLOOKUP(B15,BS!$A:$S,$C$1+4,FALSE) -> 0 | E15: =VLOOKUP(B15,BS!$A:$S,18,FALSE)-VLOOKUP(B15,BS!$A:$S,$C$1+5,FALSE) -> 0 | F15: =VLOOKUP(B15,BS!$A:$S,18,FALSE) -> 0 | G15: =E15-D15 -> 0 | H15: =IFERROR(G15/D15,0) -> 0 | I15: =F15-E15 -> 0 | J15: =IFERROR(I15/E15,0) -> 0 | L15: PL01-06 | M15: AS 용역매출액 | N15: =VLOOKUP(L15,PL!$A:$S,$C$1+3,FALSE) -> 0 | O15: =VLOOKUP(L15,PL!$A:$S,$C$1+4,FALSE) -> 0 | P15: =VLOOKUP(L15,PL!$A:$S,$C$1+5,FALSE) -> 0 | Q15: =O15-N15 -> 0 | R15: =IFERROR(Q15/N15,0) -> 0 | S15: =P15-O15 -> 0 | T15: =IFERROR(S15/O15,0) -> 0 | V15: =N76/N4 -> -0.32893378 | W15: =O76/O4 -> -0.86417765 | X15: =P76/P4 -> -0.46956912
B16: FP01-01-01-0100 | C16: 미수금 | D16: =VLOOKUP(B16,BS!$A:$S,18,FALSE)-VLOOKUP(B16,BS!$A:$S,$C$1+5,FALSE)-VLOOKUP(B16,BS!$A:$S,$C$1+4,FALSE) -> 67107803 | E16: =VLOOKUP(B16,BS!$A:$S,18,FALSE)-VLOOKUP(B16,BS!$A:$S,$C$1+5,FALSE) -> 67942511 | F16: =VLOOKUP(B16,BS!$A:$S,18,FALSE) -> 71001367 | G16: =E16-D16 -> 834708 | H16: =IFERROR(G16/D16,0) -> 0.012438315 | I16: =F16-E16 -> 3058856.7 | J16: =IFERROR(I16/E16,0) -> 0.045021248 | L16: PL01-07 | M16: 임상용역매출액 | N16: =VLOOKUP(L16,PL!$A:$S,$C$1+3,FALSE) -> 5 | O16: =VLOOKUP(L16,PL!$A:$S,$C$1+4,FALSE) -> 0 | P16: =VLOOKUP(L16,PL!$A:$S,$C$1+5,FALSE) -> 2251724.2 | Q16: =O16-N16 -> -5 | R16: =IFERROR(Q16/N16,0) -> -1 | S16: =P16-O16 -> 2251724.2 | T16: =IFERROR(S16/O16,0) -> 0
B17: FP01-01-01-0110 | C17: 대손충당금(미수금) | D17: =VLOOKUP(B17,BS!$A:$S,18,FALSE)-VLOOKUP(B17,BS!$A:$S,$C$1+5,FALSE)-VLOOKUP(B17,BS!$A:$S,$C$1+4,FALSE) -> 0 | E17: =VLOOKUP(B17,BS!$A:$S,18,FALSE)-VLOOKUP(B17,BS!$A:$S,$C$1+5,FALSE) -> 0 | F17: =VLOOKUP(B17,BS!$A:$S,18,FALSE) -> 0 | G17: =E17-D17 -> 0 | H17: =IFERROR(G17/D17,0) -> 0 | I17: =F17-E17 -> 0 | J17: =IFERROR(I17/E17,0) -> 0 | L17: PL01-08 | M17: 기타용역매출액 | N17: =VLOOKUP(L17,PL!$A:$S,$C$1+3,FALSE) -> 0 | O17: =VLOOKUP(L17,PL!$A:$S,$C$1+4,FALSE) -> 0 | P17: =VLOOKUP(L17,PL!$A:$S,$C$1+5,FALSE) -> 0 | Q17: =O17-N17 -> 0 | R17: =IFERROR(Q17/N17,0) -> 0 | S17: =P17-O17 -> 0 | T17: =IFERROR(S17/O17,0) -> 0
B18: FP01-01-01-0120 | C18: 위법행위미수금 | D18: =VLOOKUP(B18,BS!$A:$S,18,FALSE)-VLOOKUP(B18,BS!$A:$S,$C$1+5,FALSE)-VLOOKUP(B18,BS!$A:$S,$C$1+4,FALSE) -> 0 | E18: =VLOOKUP(B18,BS!$A:$S,18,FALSE)-VLOOKUP(B18,BS!$A:$S,$C$1+5,FALSE) -> 0 | F18: =VLOOKUP(B18,BS!$A:$S,18,FALSE) -> 0 | G18: =E18-D18 -> 0 | H18: =IFERROR(G18/D18,0) -> 0 | I18: =F18-E18 -> 0 | J18: =IFERROR(I18/E18,0) -> 0 | L18: PL01-09 | M18: 렌탈매출액 | N18: =VLOOKUP(L18,PL!$A:$S,$C$1+3,FALSE) -> 0 | O18: =VLOOKUP(L18,PL!$A:$S,$C$1+4,FALSE) -> 0 | P18: =VLOOKUP(L18,PL!$A:$S,$C$1+5,FALSE) -> 0 | Q18: =O18-N18 -> 0 | R18: =IFERROR(Q18/N18,0) -> 0 | S18: =P18-O18 -> 0 | T18: =IFERROR(S18/O18,0) -> 0 | V18: 영업이익금액
B19: FP01-01-01-0130 | C19: 대손충당금(위법행위미수금) | D19: =VLOOKUP(B19,BS!$A:$S,18,FALSE)-VLOOKUP(B19,BS!$A:$S,$C$1+5,FALSE)-VLOOKUP(B19,BS!$A:$S,$C$1+4,FALSE) -> 0 | E19: =VLOOKUP(B19,BS!$A:$S,18,FALSE)-VLOOKUP(B19,BS!$A:$S,$C$1+5,FALSE) -> 0 | F19: =VLOOKUP(B19,BS!$A:$S,18,FALSE) -> 0 | G19: =E19-D19 -> 0 | H19: =IFERROR(G19/D19,0) -> 0 | I19: =F19-E19 -> 0 | J19: =IFERROR(I19/E19,0) -> 0 | L19: PL01-10 | M19: 임대매출액 | N19: =VLOOKUP(L19,PL!$A:$S,$C$1+3,FALSE) -> 0 | O19: =VLOOKUP(L19,PL!$A:$S,$C$1+4,FALSE) -> 0 | P19: =VLOOKUP(L19,PL!$A:$S,$C$1+5,FALSE) -> 0 | Q19: =O19-N19 -> 0 | R19: =IFERROR(Q19/N19,0) -> 0 | S19: =P19-O19 -> 0 | T19: =IFERROR(S19/O19,0) -> 0 | V19: 전전월 | W19: 전월 | X19: 당월
B20: FP01-01-01-0140 | C20: 단기대여금 | D20: =VLOOKUP(B20,BS!$A:$S,18,FALSE)-VLOOKUP(B20,BS!$A:$S,$C$1+5,FALSE)-VLOOKUP(B20,BS!$A:$S,$C$1+4,FALSE) -> 0 | E20: =VLOOKUP(B20,BS!$A:$S,18,FALSE)-VLOOKUP(B20,BS!$A:$S,$C$1+5,FALSE) -> 0 | F20: =VLOOKUP(B20,BS!$A:$S,18,FALSE) -> 0 | G20: =E20-D20 -> 0 | H20: =IFERROR(G20/D20,0) -> 0 | I20: =F20-E20 -> 0 | J20: =IFERROR(I20/E20,0) -> 0 | L20: PL01-99 | M20: 기타매출액 | N20: =VLOOKUP(L20,PL!$A:$S,$C$1+3,FALSE) -> 0 | O20: =VLOOKUP(L20,PL!$A:$S,$C$1+4,FALSE) -> 0 | P20: =VLOOKUP(L20,PL!$A:$S,$C$1+5,FALSE) -> 0 | Q20: =O20-N20 -> 0 | R20: =IFERROR(Q20/N20,0) -> 0 | S20: =P20-O20 -> 0 | T20: =IFERROR(S20/O20,0) -> 0 | V20: =N76 -> -77451088 | W20: =O76 -> -1.2606788e+08 | X20: =P76 -> -75023007
B21: FP01-01-01-0150 | C21: 대손충당금(단기대여금) | D21: =VLOOKUP(B21,BS!$A:$S,18,FALSE)-VLOOKUP(B21,BS!$A:$S,$C$1+5,FALSE)-VLOOKUP(B21,BS!$A:$S,$C$1+4,FALSE) -> 0 | E21: =VLOOKUP(B21,BS!$A:$S,18,FALSE)-VLOOKUP(B21,BS!$A:$S,$C$1+5,FALSE) -> 0 | F21: =VLOOKUP(B21,BS!$A:$S,18,FALSE) -> 0 | G21: =E21-D21 -> 0 | H21: =IFERROR(G21/D21,0) -> 0 | I21: =F21-E21 -> 0 | J21: =IFERROR(I21/E21,0) -> 0 | L21: PL02 | M21: 매출원가 | N21: =VLOOKUP(L21,PL!$A:$S,$C$1+3,FALSE) -> 1.7680787e+08 | O21: =VLOOKUP(L21,PL!$A:$S,$C$1+4,FALSE) -> 99782884 | P21: =VLOOKUP(L21,PL!$A:$S,$C$1+5,FALSE) -> 1.2461118e+08 | Q21: =O21-N21 -> -77024987 | R21: =IFERROR(Q21/N21,0) -> -0.4356423 | S21: =P21-O21 -> 24828301 | T21: =IFERROR(S21/O21,0) -> 0.24882325
B22: FP01-01-01-0160 | C22: 미수수익 | D22: =VLOOKUP(B22,BS!$A:$S,18,FALSE)-VLOOKUP(B22,BS!$A:$S,$C$1+5,FALSE)-VLOOKUP(B22,BS!$A:$S,$C$1+4,FALSE) -> 0 | E22: =VLOOKUP(B22,BS!$A:$S,18,FALSE)-VLOOKUP(B22,BS!$A:$S,$C$1+5,FALSE) -> 0 | F22: =VLOOKUP(B22,BS!$A:$S,18,FALSE) -> 0 | G22: =E22-D22 -> 0 | H22: =IFERROR(G22/D22,0) -> 0 | I22: =F22-E22 -> 0 | J22: =IFERROR(I22/E22,0) -> 0 | L22: PL02-01 | M22: 상품매출원가 | N22: =VLOOKUP(L22,PL!$A:$S,$C$1+3,FALSE) -> 1.7680787e+08 | O22: =VLOOKUP(L22,PL!$A:$S,$C$1+4,FALSE) -> 99782884 | P22: =VLOOKUP(L22,PL!$A:$S,$C$1+5,FALSE) -> 1.2440593e+08 | Q22: =O22-N22 -> -77024987 | R22: =IFERROR(Q22/N22,0) -> -0.4356423 | S22: =P22-O22 -> 24623042 | T22: =IFERROR(S22/O22,0) -> 0.24676619
B23: FP01-01-01-0170 | C23: 선급금 | D23: =VLOOKUP(B23,BS!$A:$S,18,FALSE)-VLOOKUP(B23,BS!$A:$S,$C$1+5,FALSE)-VLOOKUP(B23,BS!$A:$S,$C$1+4,FALSE) -> 2.7163243e+08 | E23: =VLOOKUP(B23,BS!$A:$S,18,FALSE)-VLOOKUP(B23,BS!$A:$S,$C$1+5,FALSE) -> 2.958084e+08 | F23: =VLOOKUP(B23,BS!$A:$S,18,FALSE) -> 2.9714345e+08 | G23: =E23-D23 -> 24175969 | H23: =IFERROR(G23/D23,0) -> 0.089002511 | I23: =F23-E23 -> 1335049 | J23: =IFERROR(I23/E23,0) -> 0.004513222 | L23: PL02-01-0010 | M23: 본사상품매출원가 | N23: =VLOOKUP(L23,PL!$A:$S,$C$1+3,FALSE) -> 17183999 | O23: =VLOOKUP(L23,PL!$A:$S,$C$1+4,FALSE) -> 18067409 | P23: =VLOOKUP(L23,PL!$A:$S,$C$1+5,FALSE) -> 14803671 | Q23: =O23-N23 -> 883410.55 | R23: =IFERROR(Q23/N23,0) -> 0.051408904 | S23: =P23-O23 -> -3263738.4 | T23: =IFERROR(S23/O23,0) -> -0.1806423 | V23: 판관비율
B24: FP01-01-01-0180 | C24: 대손충당금(선급금) | D24: =VLOOKUP(B24,BS!$A:$S,18,FALSE)-VLOOKUP(B24,BS!$A:$S,$C$1+5,FALSE)-VLOOKUP(B24,BS!$A:$S,$C$1+4,FALSE) -> 0 | E24: =VLOOKUP(B24,BS!$A:$S,18,FALSE)-VLOOKUP(B24,BS!$A:$S,$C$1+5,FALSE) -> 0 | F24: =VLOOKUP(B24,BS!$A:$S,18,FALSE) -> 0 | G24: =E24-D24 -> 0 | H24: =IFERROR(G24/D24,0) -> 0 | I24: =F24-E24 -> 0 | J24: =IFERROR(I24/E24,0) -> 0 | L24: PL02-01-0020 | M24: 본사제품매출원가 | N24: =VLOOKUP(L24,PL!$A:$S,$C$1+3,FALSE) -> 1.5153585e+08 | O24: =VLOOKUP(L24,PL!$A:$S,$C$1+4,FALSE) -> 72856547 | P24: =VLOOKUP(L24,PL!$A:$S,$C$1+5,FALSE) -> 1.0200555e+08 | Q24: =O24-N24 -> -78679301 | R24: =IFERROR(Q24/N24,0) -> -0.51921246 | S24: =P24-O24 -> 29149005 | T24: =IFERROR(S24/O24,0) -> 0.40008765 | V24: 전전월 | W24: 전월 | X24: 당월
B25: FP01-01-01-0190 | C25: 선급비용 | D25: =VLOOKUP(B25,BS!$A:$S,18,FALSE)-VLOOKUP(B25,BS!$A:$S,$C$1+5,FALSE)-VLOOKUP(B25,BS!$A:$S,$C$1+4,FALSE) -> 4918061.1 | E25: =VLOOKUP(B25,BS!$A:$S,18,FALSE)-VLOOKUP(B25,BS!$A:$S,$C$1+5,FALSE) -> 2731275 | F25: =VLOOKUP(B25,BS!$A:$S,18,FALSE) -> 2417848.5 | G25: =E25-D25 -> -2186786.1 | H25: =IFERROR(G25/D25,0) -> -0.44464396 | I25: =F25-E25 -> -313426.49 | J25: =IFERROR(I25/E25,0) -> -0.11475465 | L25: PL02-01-0030 | M25: 미국제품매출원가 | N25: =VLOOKUP(L25,PL!$A:$S,$C$1+3,FALSE) -> 4110316.7 | O25: =VLOOKUP(L25,PL!$A:$S,$C$1+4,FALSE) -> 7812391.8 | P25: =VLOOKUP(L25,PL!$A:$S,$C$1+5,FALSE) -> 5818403.6 | Q25: =O25-N25 -> 3702075.1 | R25: =IFERROR(Q25/N25,0) -> 0.90067881 | S25: =P25-O25 -> -1993988.2 | T25: =IFERROR(S25/O25,0) -> -0.25523403 | V25: =N39/N4 -> 0.57803301 | W25: =O39/O4 -> 1.18018 | X25: =P39/P4 -> 0.68962752
B26: FP01-01-01-0200 | C26: 선급법인세 | D26: =VLOOKUP(B26,BS!$A:$S,18,FALSE)-VLOOKUP(B26,BS!$A:$S,$C$1+5,FALSE)-VLOOKUP(B26,BS!$A:$S,$C$1+4,FALSE) -> 9686552.9 | E26: =VLOOKUP(B26,BS!$A:$S,18,FALSE)-VLOOKUP(B26,BS!$A:$S,$C$1+5,FALSE) -> 9686552.9 | F26: =VLOOKUP(B26,BS!$A:$S,18,FALSE) -> 9686552.9 | G26: =E26-D26 -> 0 | H26: =IFERROR(G26/D26,0) -> 0 | I26: =F26-E26 -> 0 | J26: =IFERROR(I26/E26,0) -> 0 | L26: PL02-01-0040 | M26: 현지매입상품매출원가 | N26: =VLOOKUP(L26,PL!$A:$S,$C$1+3,FALSE) -> 3977707.5 | O26: =VLOOKUP(L26,PL!$A:$S,$C$1+4,FALSE) -> 1046535.5 | P26: =VLOOKUP(L26,PL!$A:$S,$C$1+5,FALSE) -> 1778299.2 | Q26: =O26-N26 -> -2931172 | R26: =IFERROR(Q26/N26,0) -> -0.73689984 | S26: =P26-O26 -> 731763.73 | T26: =IFERROR(S26/O26,0) -> 0.69922497
B27: FP01-01-01-0210 | C27: 선급부가세 | D27: =VLOOKUP(B27,BS!$A:$S,18,FALSE)-VLOOKUP(B27,BS!$A:$S,$C$1+5,FALSE)-VLOOKUP(B27,BS!$A:$S,$C$1+4,FALSE) -> 2248900.1 | E27: =VLOOKUP(B27,BS!$A:$S,18,FALSE)-VLOOKUP(B27,BS!$A:$S,$C$1+5,FALSE) -> 5417179 | F27: =VLOOKUP(B27,BS!$A:$S,18,FALSE) -> 8981374.1 | G27: =E27-D27 -> 3168278.9 | H27: =IFERROR(G27/D27,0) -> 1.4088126 | I27: =F27-E27 -> 3564195.2 | J27: =IFERROR(I27/E27,0) -> 0.65794303 | L27: PL02-01-0050 | M27: 기타국내관계사제품매출원가 | N27: =VLOOKUP(L27,PL!$A:$S,$C$1+3,FALSE) -> 0 | O27: =VLOOKUP(L27,PL!$A:$S,$C$1+4,FALSE) -> 0 | P27: =VLOOKUP(L27,PL!$A:$S,$C$1+5,FALSE) -> 0 | Q27: =O27-N27 -> 0 | R27: =IFERROR(Q27/N27,0) -> 0 | S27: =P27-O27 -> 0 | T27: =IFERROR(S27/O27,0) -> 0 | V27: 전월대비 증감
B28: FP01-01-01-0220 | C28: 파생상품(단기) | D28: =VLOOKUP(B28,BS!$A:$S,18,FALSE)-VLOOKUP(B28,BS!$A:$S,$C$1+5,FALSE)-VLOOKUP(B28,BS!$A:$S,$C$1+4,FALSE) -> 0 | E28: =VLOOKUP(B28,BS!$A:$S,18,FALSE)-VLOOKUP(B28,BS!$A:$S,$C$1+5,FALSE) -> 0 | F28: =VLOOKUP(B28,BS!$A:$S,18,FALSE) -> 0 | G28: =E28-D28 -> 0 | H28: =IFERROR(G28/D28,0) -> 0 | I28: =F28-E28 -> 0 | J28: =IFERROR(I28/E28,0) -> 0 | L28: PL02-02 | M28: 제품매출원가 | N28: =VLOOKUP(L28,PL!$A:$S,$C$1+3,FALSE) -> 0 | O28: =VLOOKUP(L28,PL!$A:$S,$C$1+4,FALSE) -> 0 | P28: =VLOOKUP(L28,PL!$A:$S,$C$1+5,FALSE) -> 0 | Q28: =O28-N28 -> 0 | R28: =IFERROR(Q28/N28,0) -> 0 | S28: =P28-O28 -> 0 | T28: =IFERROR(S28/O28,0) -> 0 | V28: 매출 | W28: =T4 -> 0.095200188
B29: FP01-01-01-0230 | C29: 반품계약자산 | D29: =VLOOKUP(B29,BS!$A:$S,18,FALSE)-VLOOKUP(B29,BS!$A:$S,$C$1+5,FALSE)-VLOOKUP(B29,BS!$A:$S,$C$1+4,FALSE) -> 22265421 | E29: =VLOOKUP(B29,BS!$A:$S,18,FALSE)-VLOOKUP(B29,BS!$A:$S,$C$1+5,FALSE) -> 18165291 | F29: =VLOOKUP(B29,BS!$A:$S,18,FALSE) -> 13592487 | G29: =E29-D29 -> -4100130 | H29: =IFERROR(G29/D29,0) -> -0.18414788 | I29: =F29-E29 -> -4572804 | J29: =IFERROR(I29/E29,0) -> -0.25173304 | L29: PL02-03 | M29: 반제품매출원가 | N29: =VLOOKUP(L29,PL!$A:$S,$C$1+3,FALSE) -> 0 | O29: =VLOOKUP(L29,PL!$A:$S,$C$1+4,FALSE) -> 0 | P29: =VLOOKUP(L29,PL!$A:$S,$C$1+5,FALSE) -> 0 | Q29: =O29-N29 -> 0 | R29: =IFERROR(Q29/N29,0) -> 0 | S29: =P29-O29 -> 0 | T29: =IFERROR(S29/O29,0) -> 0 | V29: 원가 | W29: =T21 -> 0.24882325
B30: FP01-01-01-0240 | C30: 수익인식자산 | D30: =VLOOKUP(B30,BS!$A:$S,18,FALSE)-VLOOKUP(B30,BS!$A:$S,$C$1+5,FALSE)-VLOOKUP(B30,BS!$A:$S,$C$1+4,FALSE) -> 3637733 | E30: =VLOOKUP(B30,BS!$A:$S,18,FALSE)-VLOOKUP(B30,BS!$A:$S,$C$1+5,FALSE) -> 6876800 | F30: =VLOOKUP(B30,BS!$A:$S,18,FALSE) -> 1756752 | G30: =E30-D30 -> 3239067 | H30: =IFERROR(G30/D30,0) -> 0.89040812 | I30: =F30-E30 -> -5120048 | J30: =IFERROR(I30/E30,0) -> -0.74453932 | L30: PL02-04 | M30: 원재료매출원가 | N30: =VLOOKUP(L30,PL!$A:$S,$C$1+3,FALSE) -> 0 | O30: =VLOOKUP(L30,PL!$A:$S,$C$1+4,FALSE) -> 0 | P30: =VLOOKUP(L30,PL!$A:$S,$C$1+5,FALSE) -> 0 | Q30: =O30-N30 -> 0 | R30: =IFERROR(Q30/N30,0) -> 0 | S30: =P30-O30 -> 0 | T30: =IFERROR(S30/O30,0) -> 0 | V30: 판관비 | W30: =T39 -> -0.36002965
B31: FP01-01-01-0250 | C31: 매각예정자산 | D31: =VLOOKUP(B31,BS!$A:$S,18,FALSE)-VLOOKUP(B31,BS!$A:$S,$C$1+5,FALSE)-VLOOKUP(B31,BS!$A:$S,$C$1+4,FALSE) -> 0 | E31: =VLOOKUP(B31,BS!$A:$S,18,FALSE)-VLOOKUP(B31,BS!$A:$S,$C$1+5,FALSE) -> 0 | F31: =VLOOKUP(B31,BS!$A:$S,18,FALSE) -> 0 | G31: =E31-D31 -> 0 | H31: =IFERROR(G31/D31,0) -> 0 | I31: =F31-E31 -> 0 | J31: =IFERROR(I31/E31,0) -> 0 | L31: PL02-05 | M31: IT매출원가 | N31: =VLOOKUP(L31,PL!$A:$S,$C$1+3,FALSE) -> 0 | O31: =VLOOKUP(L31,PL!$A:$S,$C$1+4,FALSE) -> 0 | P31: =VLOOKUP(L31,PL!$A:$S,$C$1+5,FALSE) -> 0 | Q31: =O31-N31 -> 0 | R31: =IFERROR(Q31/N31,0) -> 0 | S31: =P31-O31 -> 0 | T31: =IFERROR(S31/O31,0) -> 0 | V31: 영업이익 | W31: =T76 -> -0.40489991
B32: FP01-01-01-0260 | C32: 기타당좌자산 | D32: =VLOOKUP(B32,BS!$A:$S,18,FALSE)-VLOOKUP(B32,BS!$A:$S,$C$1+5,FALSE)-VLOOKUP(B32,BS!$A:$S,$C$1+4,FALSE) -> 0 | E32: =VLOOKUP(B32,BS!$A:$S,18,FALSE)-VLOOKUP(B32,BS!$A:$S,$C$1+5,FALSE) -> 0 | F32: =VLOOKUP(B32,BS!$A:$S,18,FALSE) -> 0 | G32: =E32-D32 -> 0 | H32: =IFERROR(G32/D32,0) -> 0 | I32: =F32-E32 -> 0 | J32: =IFERROR(I32/E32,0) -> 0 | L32: PL02-06 | M32: AS용역매출원가 | N32: =VLOOKUP(L32,PL!$A:$S,$C$1+3,FALSE) -> 0 | O32: =VLOOKUP(L32,PL!$A:$S,$C$1+4,FALSE) -> 0 | P32: =VLOOKUP(L32,PL!$A:$S,$C$1+5,FALSE) -> 0 | Q32: =O32-N32 -> 0 | R32: =IFERROR(Q32/N32,0) -> 0 | S32: =P32-O32 -> 0 | T32: =IFERROR(S32/O32,0) -> 0
B33: FP01-01-02 | C33: 재고자산 | D33: =VLOOKUP(B33,BS!$A:$S,18,FALSE)-VLOOKUP(B33,BS!$A:$S,$C$1+5,FALSE)-VLOOKUP(B33,BS!$A:$S,$C$1+4,FALSE) -> 9.9349435e+08 | E33: =VLOOKUP(B33,BS!$A:$S,18,FALSE)-VLOOKUP(B33,BS!$A:$S,$C$1+5,FALSE) -> 1.0937078e+09 | F33: =VLOOKUP(B33,BS!$A:$S,18,FALSE) -> 1.1092577e+09 | G33: =E33-D33 -> 1.002134e+08 | H33: =IFERROR(G33/D33,0) -> 0.10086963 | I33: =F33-E33 -> 15549909 | J33: =IFERROR(I33/E33,0) -> 0.014217609 | L33: PL02-07 | M33: 임상용역매출원가 | N33: =VLOOKUP(L33,PL!$A:$S,$C$1+3,FALSE) -> 0 | O33: =VLOOKUP(L33,PL!$A:$S,$C$1+4,FALSE) -> 0 | P33: =VLOOKUP(L33,PL!$A:$S,$C$1+5,FALSE) -> 205258.92 | Q33: =O33-N33 -> 0 | R33: =IFERROR(Q33/N33,0) -> 0 | S33: =P33-O33 -> 205258.92 | T33: =IFERROR(S33/O33,0) -> 0
B34: FP01-01-02-0010 | C34: 상품 | D34: =VLOOKUP(B34,BS!$A:$S,18,FALSE)-VLOOKUP(B34,BS!$A:$S,$C$1+5,FALSE)-VLOOKUP(B34,BS!$A:$S,$C$1+4,FALSE) -> 1.3060418e+09 | E34: =VLOOKUP(B34,BS!$A:$S,18,FALSE)-VLOOKUP(B34,BS!$A:$S,$C$1+5,FALSE) -> 1.4069513e+09 | F34: =VLOOKUP(B34,BS!$A:$S,18,FALSE) -> 1.4347897e+09 | G34: =E34-D34 -> 1.0090952e+08 | H34: =IFERROR(G34/D34,0) -> 0.077263624 | I34: =F34-E34 -> 27838330 | J34: =IFERROR(I34/E34,0) -> 0.019786278 | L34: PL02-08 | M34: 기타용역매출원가 | N34: =VLOOKUP(L34,PL!$A:$S,$C$1+3,FALSE) -> 0 | O34: =VLOOKUP(L34,PL!$A:$S,$C$1+4,FALSE) -> 0 | P34: =VLOOKUP(L34,PL!$A:$S,$C$1+5,FALSE) -> 0 | Q34: =O34-N34 -> 0 | R34: =IFERROR(Q34/N34,0) -> 0 | S34: =P34-O34 -> 0 | T34: =IFERROR(S34/O34,0) -> 0
B35: FP01-01-02-0010-01 | C35: 본사상품매입분 | D35: =VLOOKUP(B35,BS!$A:$S,18,FALSE)-VLOOKUP(B35,BS!$A:$S,$C$1+5,FALSE)-VLOOKUP(B35,BS!$A:$S,$C$1+4,FALSE) -> 2.5243191e+08 | E35: =VLOOKUP(B35,BS!$A:$S,18,FALSE)-VLOOKUP(B35,BS!$A:$S,$C$1+5,FALSE) -> 2.9958671e+08 | F35: =VLOOKUP(B35,BS!$A:$S,18,FALSE) -> 2.6429556e+08 | G35: =E35-D35 -> 47154796 | H35: =IFERROR(G35/D35,0) -> 0.18680204 | I35: =F35-E35 -> -35291143 | J35: =IFERROR(I35/E35,0) -> -0.11779943 | L35: PL02-09 | M35: 렌탈매출원가 | N35: =VLOOKUP(L35,PL!$A:$S,$C$1+3,FALSE) -> 0 | O35: =VLOOKUP(L35,PL!$A:$S,$C$1+4,FALSE) -> 0 | P35: =VLOOKUP(L35,PL!$A:$S,$C$1+5,FALSE) -> 0 | Q35: =O35-N35 -> 0 | R35: =IFERROR(Q35/N35,0) -> 0 | S35: =P35-O35 -> 0 | T35: =IFERROR(S35/O35,0) -> 0
B36: FP01-01-02-0010-02 | C36: 본사제품매입분 | D36: =VLOOKUP(B36,BS!$A:$S,18,FALSE)-VLOOKUP(B36,BS!$A:$S,$C$1+5,FALSE)-VLOOKUP(B36,BS!$A:$S,$C$1+4,FALSE) -> 9.394409e+08 | E36: =VLOOKUP(B36,BS!$A:$S,18,FALSE)-VLOOKUP(B36,BS!$A:$S,$C$1+5,FALSE) -> 9.9863636e+08 | F36: =VLOOKUP(B36,BS!$A:$S,18,FALSE) -> 1.0575197e+09 | G36: =E36-D36 -> 59195465 | H36: =IFERROR(G36/D36,0) -> 0.063011378 | I36: =F36-E36 -> 58883385 | J36: =IFERROR(I36/E36,0) -> 0.05896379 | L36: PL02-10 | M36: 임대매출원가 | N36: =VLOOKUP(L36,PL!$A:$S,$C$1+3,FALSE) -> 0 | O36: =VLOOKUP(L36,PL!$A:$S,$C$1+4,FALSE) -> 0 | P36: =VLOOKUP(L36,PL!$A:$S,$C$1+5,FALSE) -> 0 | Q36: =O36-N36 -> 0 | R36: =IFERROR(Q36/N36,0) -> 0 | S36: =P36-O36 -> 0 | T36: =IFERROR(S36/O36,0) -> 0
B37: FP01-01-02-0010-03 | C37: 미국제품매입분 | D37: =VLOOKUP(B37,BS!$A:$S,18,FALSE)-VLOOKUP(B37,BS!$A:$S,$C$1+5,FALSE)-VLOOKUP(B37,BS!$A:$S,$C$1+4,FALSE) -> 34134290 | E37: =VLOOKUP(B37,BS!$A:$S,18,FALSE)-VLOOKUP(B37,BS!$A:$S,$C$1+5,FALSE) -> 29524000 | F37: =VLOOKUP(B37,BS!$A:$S,18,FALSE) -> 30676980 | G37: =E37-D37 -> -4610290.2 | H37: =IFERROR(G37/D37,0) -> -0.13506331 | I37: =F37-E37 -> 1152980.1 | J37: =IFERROR(I37/E37,0) -> 0.039052299 | L37: PL02-99 | M37: 기타매출원가 | N37: =VLOOKUP(L37,PL!$A:$S,$C$1+3,FALSE) -> 0 | O37: =VLOOKUP(L37,PL!$A:$S,$C$1+4,FALSE) -> 0 | P37: =VLOOKUP(L37,PL!$A:$S,$C$1+5,FALSE) -> 0 | Q37: =O37-N37 -> 0 | R37: =IFERROR(Q37/N37,0) -> 0 | S37: =P37-O37 -> 0 | T37: =IFERROR(S37/O37,0) -> 0
B38: FP01-01-02-0010-04 | C38: 현지매입분 | D38: =VLOOKUP(B38,BS!$A:$S,18,FALSE)-VLOOKUP(B38,BS!$A:$S,$C$1+5,FALSE)-VLOOKUP(B38,BS!$A:$S,$C$1+4,FALSE) -> 80034705 | E38: =VLOOKUP(B38,BS!$A:$S,18,FALSE)-VLOOKUP(B38,BS!$A:$S,$C$1+5,FALSE) -> 79204257 | F38: =VLOOKUP(B38,BS!$A:$S,18,FALSE) -> 82297365 | G38: =E38-D38 -> -830447.89 | H38: =IFERROR(G38/D38,0) -> -0.010376097 | I38: =F38-E38 -> 3093108.3 | J38: =IFERROR(I38/E38,0) -> 0.039052299 | L38: PL03 | M38: 매출총이익 | N38: =VLOOKUP(L38,PL!$A:$S,$C$1+3,FALSE) -> 58653160 | O38: =VLOOKUP(L38,PL!$A:$S,$C$1+4,FALSE) -> 46099022 | P38: =VLOOKUP(L38,PL!$A:$S,$C$1+5,FALSE) -> 35158706 | Q38: =O38-N38 -> -12554138 | R38: =IFERROR(Q38/N38,0) -> -0.21404027 | S38: =P38-O38 -> -10940316 | T38: =IFERROR(S38/O38,0) -> -0.23732209
B39: FP01-01-02-0010-05 | C39: 기타관계사매입분 | D39: =VLOOKUP(B39,BS!$A:$S,18,FALSE)-VLOOKUP(B39,BS!$A:$S,$C$1+5,FALSE)-VLOOKUP(B39,BS!$A:$S,$C$1+4,FALSE) -> 0 | E39: =VLOOKUP(B39,BS!$A:$S,18,FALSE)-VLOOKUP(B39,BS!$A:$S,$C$1+5,FALSE) -> 0 | F39: =VLOOKUP(B39,BS!$A:$S,18,FALSE) -> 0 | G39: =E39-D39 -> 0 | H39: =IFERROR(G39/D39,0) -> 0 | I39: =F39-E39 -> 0 | J39: =IFERROR(I39/E39,0) -> 0 | L39: PL04 | M39: 판매비와 관리비 | N39: =VLOOKUP(L39,PL!$A:$S,$C$1+3,FALSE) -> 1.3610425e+08 | O39: =VLOOKUP(L39,PL!$A:$S,$C$1+4,FALSE) -> 1.721669e+08 | P39: =VLOOKUP(L39,PL!$A:$S,$C$1+5,FALSE) -> 1.1018171e+08 | Q39: =O39-N39 -> 36062656 | R39: =IFERROR(Q39/N39,0) -> 0.26496348 | S39: =P39-O39 -> -61985191 | T39: =IFERROR(S39/O39,0) -> -0.36002965
B40: FP01-01-02-0020 | C40: 상품충당금 | D40: =VLOOKUP(B40,BS!$A:$S,18,FALSE)-VLOOKUP(B40,BS!$A:$S,$C$1+5,FALSE)-VLOOKUP(B40,BS!$A:$S,$C$1+4,FALSE) -> -3.1999449e+08 | E40: =VLOOKUP(B40,BS!$A:$S,18,FALSE)-VLOOKUP(B40,BS!$A:$S,$C$1+5,FALSE) -> -3.2101648e+08 | F40: =VLOOKUP(B40,BS!$A:$S,18,FALSE) -> -3.3371923e+08 | G40: =E40-D40 -> -1021982.1 | H40: =IFERROR(G40/D40,0) -> 0.0031937491 | I40: =F40-E40 -> -12702756 | J40: =IFERROR(I40/E40,0) -> 0.039570418 | L40: PL04-00-0010 | M40: 급여 | N40: =VLOOKUP(L40,PL!$A:$S,$C$1+3,FALSE) -> 61116484 | O40: =VLOOKUP(L40,PL!$A:$S,$C$1+4,FALSE) -> 69099494 | P40: =VLOOKUP(L40,PL!$A:$S,$C$1+5,FALSE) -> 62213260 | Q40: =O40-N40 -> 7983010.2 | R40: =IFERROR(Q40/N40,0) -> 0.13061959 | S40: =P40-O40 -> -6886234.6 | T40: =IFERROR(S40/O40,0) -> -0.099656801
...

Sheet 년 비교
P1: 원가율
F2: 전년 대비 당해 | M2: 전년 대비 당해 | P2: 전년 | Q2: 당해
B3: 연결계정 | C3: 연결계정명 | D3: 전년(A) | E3: 당해(B) | F3: 증감(B-A) | G3: % | I3: 연결계정 | J3: 연결계정명 | K3: 전년(A) | L3: 당해(B) | M3: 증감(B-A) | N3: % | P3: =K21/K4 -> 0.72662313 | Q3: =L21/L4 -> 0.7414386
B4: FP01 | C4: 자산 | D4: =VLOOKUP(B4,BS!$A:$S,5,FALSE) -> 2.8792115e+09 | E4: =VLOOKUP(B4,BS!$A:$S,18,FALSE) -> 2.4941833e+09 | F4: =E4-D4 -> -3.8502829e+08 | G4: =IFERROR(F4/D4,0) -> -0.13372699 | I4: PL01 | J4: 매출액 | K4: =VLOOKUP(I4,PL!$A:$S,4,FALSE) -> 1.431649e+09 | L4: =VLOOKUP(I4,PL!$A:$S,18,FALSE) -> 5.4111283e+08 | M4: =L4-K4 -> -8.9053612e+08 | N4: =IFERROR(M4/K4,0) -> -0.62203526
B5: FP01-01 | C5: 유동자산 | D5: =VLOOKUP(B5,BS!$A:$S,5,FALSE) -> 2.65277e+09 | E5: =VLOOKUP(B5,BS!$A:$S,18,FALSE) -> 2.2830502e+09 | F5: =E5-D5 -> -3.6971986e+08 | G5: =IFERROR(F5/D5,0) -> -0.13937124 | I5: PL01-01 | J5: 상품매출액 | K5: =VLOOKUP(I5,PL!$A:$S,4,FALSE) -> 1.4309649e+09 | L5: =VLOOKUP(I5,PL!$A:$S,18,FALSE) -> 5.388611e+08 | M5: =L5-K5 -> -8.9210379e+08 | N5: =IFERROR(M5/K5,0) -> -0.62342815 | P5: 유동비율
B6: FP01-01-01 | C6: 당좌자산 | D6: =VLOOKUP(B6,BS!$A:$S,5,FALSE) -> 1.5162714e+09 | E6: =VLOOKUP(B6,BS!$A:$S,18,FALSE) -> 1.1737925e+09 | F6: =E6-D6 -> -3.4247887e+08 | G6: =IFERROR(F6/D6,0) -> -0.22586911 | I6: PL01-01-0010 | J6: 본사상품매출액 | K6: =VLOOKUP(I6,PL!$A:$S,4,FALSE) -> 134957920 | L6: =VLOOKUP(I6,PL!$A:$S,18,FALSE) -> 45028810 | M6: =L6-K6 -> -89929110 | N6: =IFERROR(M6/K6,0) -> -0.66634926 | P6: 전년 | Q6: 당해
B7: FP01-01-01-0010 | C7: 현금및현금성자산 | D7: =VLOOKUP(B7,BS!$A:$S,5,FALSE) -> 6.0413375e+08 | E7: =VLOOKUP(B7,BS!$A:$S,18,FALSE) -> 4.7915504e+08 | F7: =E7-D7 -> -1.2497871e+08 | G7: =IFERROR(F7/D7,0) -> -0.20687258 | I7: PL01-01-0020 | J7: 본사제품매출액 | K7: =VLOOKUP(I7,PL!$A:$S,4,FALSE) -> 1.2375628e+09 | L7: =VLOOKUP(I7,PL!$A:$S,18,FALSE) -> 4.7286917e+08 | M7: =L7-K7 -> -7.6469361e+08 | N7: =IFERROR(M7/K7,0) -> -0.61790288 | P7: =D5/D114 -> 0.68836247 | Q7: =E5/E114 -> 0.63036042
B8: FP01-01-01-0020 | C8: 국고보조금(현금) | D8: =VLOOKUP(B8,BS!$A:$S,5,FALSE) -> 0 | E8: =VLOOKUP(B8,BS!$A:$S,18,FALSE) -> 0 | F8: =E8-D8 -> 0 | G8: =IFERROR(F8/D8,0) -> 0 | I8: PL01-01-0030 | J8: 미국제품매출액 | K8: =VLOOKUP(I8,PL!$A:$S,4,FALSE) -> 34431650 | L8: =VLOOKUP(I8,PL!$A:$S,18,FALSE) -> 14592006 | M8: =L8-K8 -> -19839645 | N8: =IFERROR(M8/K8,0) -> -0.57620371
B9: FP01-01-01-0030 | C9: 단기금융상품 | D9: =VLOOKUP(B9,BS!$A:$S,5,FALSE) -> 0 | E9: =VLOOKUP(B9,BS!$A:$S,18,FALSE) -> 0 | F9: =E9-D9 -> 0 | G9: =IFERROR(F9/D9,0) -> 0 | I9: PL01-01-0040 | J9: 현지매입상품매출액 | K9: =VLOOKUP(I9,PL!$A:$S,4,FALSE) -> 24012532 | L9: =VLOOKUP(I9,PL!$A:$S,18,FALSE) -> 6371110.3 | M9: =L9-K9 -> -17641422 | N9: =IFERROR(M9/K9,0) -> -0.73467561 | P9: 부채비율
B10: FP01-01-01-0040 | C10: 단기매매증권 | D10: =VLOOKUP(B10,BS!$A:$S,5,FALSE) -> 0 | E10: =VLOOKUP(B10,BS!$A:$S,18,FALSE) -> 0 | F10: =E10-D10 -> 0 | G10: =IFERROR(F10/D10,0) -> 0 | I10: PL01-01-0050 | J10: 기타관계사제품매출액 | K10: =VLOOKUP(I10,PL!$A:$S,4,FALSE) -> 0 | L10: =VLOOKUP(I10,PL!$A:$S,18,FALSE) -> 0 | M10: =L10-K10 -> 0 | N10: =IFERROR(M10/K10,0) -> 0 | P10: 전년 | Q10: 당해
B11: FP01-01-01-0050 | C11: 만기보유증권 | D11: =VLOOKUP(B11,BS!$A:$S,5,FALSE) -> 0 | E11: =VLOOKUP(B11,BS!$A:$S,18,FALSE) -> 0 | F11: =E11-D11 -> 0 | G11: =IFERROR(F11/D11,0) -> 0 | I11: PL01-02 | J11: 제품매출액 | K11: =VLOOKUP(I11,PL!$A:$S,4,FALSE) -> 0 | L11: =VLOOKUP(I11,PL!$A:$S,18,FALSE) -> 0 | M11: =L11-K11 -> 0 | N11: =IFERROR(M11/K11,0) -> 0 | P11: =D113/D162 -> -3.9544661 | Q11: =E113/E162 -> -3.2118733
B12: FP01-01-01-0060 | C12: 매도가능증권 | D12: =VLOOKUP(B12,BS!$A:$S,5,FALSE) -> 0 | E12: =VLOOKUP(B12,BS!$A:$S,18,FALSE) -> 0 | F12: =E12-D12 -> 0 | G12: =IFERROR(F12/D12,0) -> 0 | I12: PL01-03 | J12: 반제품매출액 | K12: =VLOOKUP(I12,PL!$A:$S,4,FALSE) -> 0 | L12: =VLOOKUP(I12,PL!$A:$S,18,FALSE) -> 0 | M12: =L12-K12 -> 0 | N12: =IFERROR(M12/K12,0) -> 0
B13: FP01-01-01-0070 | C13: 매출채권 | D13: =VLOOKUP(B13,BS!$A:$S,5,FALSE) -> 7.1296815e+08 | E13: =VLOOKUP(B13,BS!$A:$S,18,FALSE) -> 5.6025549e+08 | F13: =E13-D13 -> -1.5271266e+08 | G13: =IFERROR(F13/D13,0) -> -0.21419282 | I13: PL01-04 | J13: 원재료매출액 | K13: =VLOOKUP(I13,PL!$A:$S,4,FALSE) -> 0 | L13: =VLOOKUP(I13,PL!$A:$S,18,FALSE) -> 0 | M13: =L13-K13 -> 0 | N13: =IFERROR(M13/K13,0) -> 0 | P13: 영업이익율
B14: FP01-01-01-0080 | C14: 대손충당금(매출채권) | D14: =VLOOKUP(B14,BS!$A:$S,5,FALSE) -> -1.8260338e+08 | E14: =VLOOKUP(B14,BS!$A:$S,18,FALSE) -> -2.7019784e+08 | F14: =E14-D14 -> -87594463 | G14: =IFERROR(F14/D14,0) -> 0.47969792 | I14: PL01-05 | J14: IT매출액 | K14: =VLOOKUP(I14,PL!$A:$S,4,FALSE) -> 0 | L14: =VLOOKUP(I14,PL!$A:$S,18,FALSE) -> 0 | M14: =L14-K14 -> 0 | N14: =IFERROR(M14/K14,0) -> 0 | P14: 전년 | Q14: 당해
B15: FP01-01-01-0090 | C15: 현재가치할인차금(단기) | D15: =VLOOKUP(B15,BS!$A:$S,5,FALSE) -> 0 | E15: =VLOOKUP(B15,BS!$A:$S,18,FALSE) -> 0 | F15: =E15-D15 -> 0 | G15: =IFERROR(F15/D15,0) -> 0 | I15: PL01-06 | J15: AS 용역매출액 | K15: =VLOOKUP(I15,PL!$A:$S,4,FALSE) -> 0 | L15: =VLOOKUP(I15,PL!$A:$S,18,FALSE) -> 0 | M15: =L15-K15 -> 0 | N15: =IFERROR(M15/K15,0) -> 0 | P15: =K76/K4 -> -0.10250443 | Q15: =L76/L4 -> -0.51475767
B16: FP01-01-01-0100 | C16: 미수금 | D16: =VLOOKUP(B16,BS!$A:$S,5,FALSE) -> 65612313 | E16: =VLOOKUP(B16,BS!$A:$S,18,FALSE) -> 71001367 | F16: =E16-D16 -> 5389054.3 | G16: =IFERROR(F16/D16,0) -> 0.082134802 | I16: PL01-07 | J16: 임상용역매출액 | K16: =VLOOKUP(I16,PL!$A:$S,4,FALSE) -> 684066 | L16: =VLOOKUP(I16,PL!$A:$S,18,FALSE) -> 2251729.2 | M16: =L16-K16 -> 1567663.2 | N16: =IFERROR(M16/K16,0) -> 2.2916841
B17: FP01-01-01-0110 | C17: 대손충당금(미수금) | D17: =VLOOKUP(B17,BS!$A:$S,5,FALSE) -> 0 | E17: =VLOOKUP(B17,BS!$A:$S,18,FALSE) -> 0 | F17: =E17-D17 -> 0 | G17: =IFERROR(F17/D17,0) -> 0 | I17: PL01-08 | J17: 기타용역매출액 | K17: =VLOOKUP(I17,PL!$A:$S,4,FALSE) -> 0 | L17: =VLOOKUP(I17,PL!$A:$S,18,FALSE) -> 0 | M17: =L17-K17 -> 0 | N17: =IFERROR(M17/K17,0) -> 0 | P17: 영업이익 금액
B18: FP01-01-01-0120 | C18: 위법행위미수금 | D18: =VLOOKUP(B18,BS!$A:$S,5,FALSE) -> 0 | E18: =VLOOKUP(B18,BS!$A:$S,18,FALSE) -> 0 | F18: =E18-D18 -> 0 | G18: =IFERROR(F18/D18,0) -> 0 | I18: PL01-09 | J18: 렌탈매출액 | K18: =VLOOKUP(I18,PL!$A:$S,4,FALSE) -> 0 | L18: =VLOOKUP(I18,PL!$A:$S,18,FALSE) -> 0 | M18: =L18-K18 -> 0 | N18: =IFERROR(M18/K18,0) -> 0 | P18: 전년 | Q18: 당해
B19: FP01-01-01-0130 | C19: 대손충당금(위법행위미수금) | D19: =VLOOKUP(B19,BS!$A:$S,5,FALSE) -> 0 | E19: =VLOOKUP(B19,BS!$A:$S,18,FALSE) -> 0 | F19: =E19-D19 -> 0 | G19: =IFERROR(F19/D19,0) -> 0 | I19: PL01-10 | J19: 임대매출액 | K19: =VLOOKUP(I19,PL!$A:$S,4,FALSE) -> 0 | L19: =VLOOKUP(I19,PL!$A:$S,18,FALSE) -> 0 | M19: =L19-K19 -> 0 | N19: =IFERROR(M19/K19,0) -> 0 | P19: =K76 -> -1.4675036e+08 | Q19: =L76 -> -2.7854198e+08
B20: FP01-01-01-0140 | C20: 단기대여금 | D20: =VLOOKUP(B20,BS!$A:$S,5,FALSE) -> 0 | E20: =VLOOKUP(B20,BS!$A:$S,18,FALSE) -> 0 | F20: =E20-D20 -> 0 | G20: =IFERROR(F20/D20,0) -> 0 | I20: PL01-99 | J20: 기타매출액 | K20: =VLOOKUP(I20,PL!$A:$S,4,FALSE) -> 0 | L20: =VLOOKUP(I20,PL!$A:$S,18,FALSE) -> 0 | M20: =L20-K20 -> 0 | N20: =IFERROR(M20/K20,0) -> 0
B21: FP01-01-01-0150 | C21: 대손충당금(단기대여금) | D21: =VLOOKUP(B21,BS!$A:$S,5,FALSE) -> 0 | E21: =VLOOKUP(B21,BS!$A:$S,18,FALSE) -> 0 | F21: =E21-D21 -> 0 | G21: =IFERROR(F21/D21,0) -> 0 | I21: PL02 | J21: 매출원가 | K21: =VLOOKUP(I21,PL!$A:$S,4,FALSE) -> 1.0402692e+09 | L21: =VLOOKUP(I21,PL!$A:$S,18,FALSE) -> 4.0120194e+08 | M21: =L21-K21 -> -6.390673e+08 | N21: =IFERROR(M21/K21,0) -> -0.61432875 | P21: 판관비율
B22: FP01-01-01-0160 | C22: 미수수익 | D22: =VLOOKUP(B22,BS!$A:$S,5,FALSE) -> 0 | E22: =VLOOKUP(B22,BS!$A:$S,18,FALSE) -> 0 | F22: =E22-D22 -> 0 | G22: =IFERROR(F22/D22,0) -> 0 | I22: PL02-01 | J22: 상품매출원가 | K22: =VLOOKUP(I22,PL!$A:$S,4,FALSE) -> 1.0163239e+09 | L22: =VLOOKUP(I22,PL!$A:$S,18,FALSE) -> 4.0099668e+08 | M22: =L22-K22 -> -6.1532726e+08 | N22: =IFERROR(M22/K22,0) -> -0.60544403 | P22: 전년 | Q22: 당해
B23: FP01-01-01-0170 | C23: 선급금 | D23: =VLOOKUP(B23,BS!$A:$S,5,FALSE) -> 2.6572807e+08 | E23: =VLOOKUP(B23,BS!$A:$S,18,FALSE) -> 2.9714345e+08 | F23: =E23-D23 -> 31415384 | G23: =IFERROR(F23/D23,0) -> 0.11822381 | I23: PL02-01-0010 | J23: 본사상품매출원가 | K23: =VLOOKUP(I23,PL!$A:$S,4,FALSE) -> 1.0531759e+08 | L23: =VLOOKUP(I23,PL!$A:$S,18,FALSE) -> 50055079 | M23: =L23-K23 -> -55262514 | N23: =IFERROR(M23/K23,0) -> -0.52472253 | P23: =K39/K4 -> 0.3758813 | Q23: =L39/L4 -> 0.77331906
B24: FP01-01-01-0180 | C24: 대손충당금(선급금) | D24: =VLOOKUP(B24,BS!$A:$S,5,FALSE) -> 0 | E24: =VLOOKUP(B24,BS!$A:$S,18,FALSE) -> 0 | F24: =E24-D24 -> 0 | G24: =IFERROR(F24/D24,0) -> 0 | I24: PL02-01-0020 | J24: 본사제품매출원가 | K24: =VLOOKUP(I24,PL!$A:$S,4,FALSE) -> 8.662673e+08 | L24: =VLOOKUP(I24,PL!$A:$S,18,FALSE) -> 3.2639795e+08 | M24: =L24-K24 -> -5.3986936e+08 | N24: =IFERROR(M24/K24,0) -> -0.62321336
B25: FP01-01-01-0190 | C25: 선급비용 | D25: =VLOOKUP(B25,BS!$A:$S,5,FALSE) -> 3856421.5 | E25: =VLOOKUP(B25,BS!$A:$S,18,FALSE) -> 2417848.5 | F25: =E25-D25 -> -1438573 | G25: =IFERROR(F25/D25,0) -> -0.37303314 | I25: PL02-01-0030 | J25: 미국제품매출원가 | K25: =VLOOKUP(I25,PL!$A:$S,4,FALSE) -> 28582593 | L25: =VLOOKUP(I25,PL!$A:$S,18,FALSE) -> 17741112 | M25: =L25-K25 -> -10841481 | N25: =IFERROR(M25/K25,0) -> -0.37930362 | P25: 전년대비 증감
B26: FP01-01-01-0200 | C26: 선급법인세 | D26: =VLOOKUP(B26,BS!$A:$S,5,FALSE) -> 9686552.9 | E26: =VLOOKUP(B26,BS!$A:$S,18,FALSE) -> 9686552.9 | F26: =E26-D26 -> 0 | G26: =IFERROR(F26/D26,0) -> 0 | I26: PL02-01-0040 | J26: 현지매입상품매출원가 | K26: =VLOOKUP(I26,PL!$A:$S,4,FALSE) -> 16156445 | L26: =VLOOKUP(I26,PL!$A:$S,18,FALSE) -> 6802542.2 | M26: =L26-K26 -> -9353903.3 | N26: =IFERROR(M26/K26,0) -> -0.578958 | P26: 매출 | Q26: =N4 -> -0.62203526
B27: FP01-01-01-0210 | C27: 선급부가세 | D27: =VLOOKUP(B27,BS!$A:$S,5,FALSE) -> 0 | E27: =VLOOKUP(B27,BS!$A:$S,18,FALSE) -> 8981374.1 | F27: =E27-D27 -> 8981374.1 | G27: =IFERROR(F27/D27,0) -> 0 | I27: PL02-01-0050 | J27: 기타국내관계사제품매출원가 | K27: =VLOOKUP(I27,PL!$A:$S,4,FALSE) -> 0 | L27: =VLOOKUP(I27,PL!$A:$S,18,FALSE) -> 0 | M27: =L27-K27 -> 0 | N27: =IFERROR(M27/K27,0) -> 0 | P27: 원가 | Q27: =N21 -> -0.61432875
B28: FP01-01-01-0220 | C28: 파생상품(단기) | D28: =VLOOKUP(B28,BS!$A:$S,5,FALSE) -> 0 | E28: =VLOOKUP(B28,BS!$A:$S,18,FALSE) -> 0 | F28: =E28-D28 -> 0 | G28: =IFERROR(F28/D28,0) -> 0 | I28: PL02-02 | J28: 제품매출원가 | K28: =VLOOKUP(I28,PL!$A:$S,4,FALSE) -> 0 | L28: =VLOOKUP(I28,PL!$A:$S,18,FALSE) -> 0 | M28: =L28-K28 -> 0 | N28: =IFERROR(M28/K28,0) -> 0 | P28: 판관비 | Q28: =N39 -> -0.22239457
B29: FP01-01-01-0230 | C29: 반품계약자산 | D29: =VLOOKUP(B29,BS!$A:$S,5,FALSE) -> 24796957 | E29: =VLOOKUP(B29,BS!$A:$S,18,FALSE) -> 13592487 | F29: =E29-D29 -> -11204470 | G29: =IFERROR(F29/D29,0) -> -0.45184859 | I29: PL02-03 | J29: 반제품매출원가 | K29: =VLOOKUP(I29,PL!$A:$S,4,FALSE) -> 0 | L29: =VLOOKUP(I29,PL!$A:$S,18,FALSE) -> 0 | M29: =L29-K29 -> 0 | N29: =IFERROR(M29/K29,0) -> 0
B30: FP01-01-01-0240 | C30: 수익인식자산 | D30: =VLOOKUP(B30,BS!$A:$S,5,FALSE) -> 12092560 | E30: =VLOOKUP(B30,BS!$A:$S,18,FALSE) -> 1756752 | F30: =E30-D30 -> -10335808 | G30: =IFERROR(F30/D30,0) -> -0.85472456 | I30: PL02-04 | J30: 원재료매출원가 | K30: =VLOOKUP(I30,PL!$A:$S,4,FALSE) -> 0 | L30: =VLOOKUP(I30,PL!$A:$S,18,FALSE) -> 0 | M30: =L30-K30 -> 0 | N30: =IFERROR(M30/K30,0) -> 0
B31: FP01-01-01-0250 | C31: 매각예정자산 | D31: =VLOOKUP(B31,BS!$A:$S,5,FALSE) -> 0 | E31: =VLOOKUP(B31,BS!$A:$S,18,FALSE) -> 0 | F31: =E31-D31 -> 0 | G31: =IFERROR(F31/D31,0) -> 0 | I31: PL02-05 | J31: IT매출원가 | K31: =VLOOKUP(I31,PL!$A:$S,4,FALSE) -> 0 | L31: =VLOOKUP(I31,PL!$A:$S,18,FALSE) -> 0 | M31: =L31-K31 -> 0 | N31: =IFERROR(M31/K31,0) -> 0
B32: FP01-01-01-0260 | C32: 기타당좌자산 | D32: =VLOOKUP(B32,BS!$A:$S,5,FALSE) -> 0 | E32: =VLOOKUP(B32,BS!$A:$S,18,FALSE) -> 0 | F32: =E32-D32 -> 0 | G32: =IFERROR(F32/D32,0) -> 0 | I32: PL02-06 | J32: AS용역매출원가 | K32: =VLOOKUP(I32,PL!$A:$S,4,FALSE) -> 0 | L32: =VLOOKUP(I32,PL!$A:$S,18,FALSE) -> 0 | M32: =L32-K32 -> 0 | N32: =IFERROR(M32/K32,0) -> 0
B33: FP01-01-02 | C33: 재고자산 | D33: =VLOOKUP(B33,BS!$A:$S,5,FALSE) -> 1.1364987e+09 | E33: =VLOOKUP(B33,BS!$A:$S,18,FALSE) -> 1.1092577e+09 | F33: =E33-D33 -> -27240992 | G33: =IFERROR(F33/D33,0) -> -0.023969225 | I33: PL02-07 | J33: 임상용역매출원가 | K33: =VLOOKUP(I33,PL!$A:$S,4,FALSE) -> 23826119 | L33: =VLOOKUP(I33,PL!$A:$S,18,FALSE) -> 205258.92 | M33: =L33-K33 -> -23620860 | N33: =IFERROR(M33/K33,0) -> -0.99138513
B34: FP01-01-02-0010 | C34: 상품 | D34: =VLOOKUP(B34,BS!$A:$S,5,FALSE) -> 1.4420218e+09 | E34: =VLOOKUP(B34,BS!$A:$S,18,FALSE) -> 1.4347897e+09 | F34: =E34-D34 -> -7232145.4 | G34: =IFERROR(F34/D34,0) -> -0.0050152816 | I34: PL02-08 | J34: 기타용역매출원가 | K34: =VLOOKUP(I34,PL!$A:$S,4,FALSE) -> 119188.04 | L34: =VLOOKUP(I34,PL!$A:$S,18,FALSE) -> 0 | M34: =L34-K34 -> -119188.04 | N34: =IFERROR(M34/K34,0) -> -1
B35: FP01-01-02-0010-01 | C35: 본사상품매입분 | D35: =VLOOKUP(B35,BS!$A:$S,5,FALSE) -> 2.6235418e+08 | E35: =VLOOKUP(B35,BS!$A:$S,18,FALSE) -> 2.6429556e+08 | F35: =E35-D35 -> 1941380 | G35: =IFERROR(F35/D35,0) -> 0.0073998439 | I35: PL02-09 | J35: 렌탈매출원가 | K35: =VLOOKUP(I35,PL!$A:$S,4,FALSE) -> 0 | L35: =VLOOKUP(I35,PL!$A:$S,18,FALSE) -> 0 | M35: =L35-K35 -> 0 | N35: =IFERROR(M35/K35,0) -> 0
B36: FP01-01-02-0010-02 | C36: 본사제품매입분 | D36: =VLOOKUP(B36,BS!$A:$S,5,FALSE) -> 1.0599504e+09 | E36: =VLOOKUP(B36,BS!$A:$S,18,FALSE) -> 1.0575197e+09 | F36: =E36-D36 -> -2430643.9 | G36: =IFERROR(F36/D36,0) -> -0.0022931676 | I36: PL02-10 | J36: 임대매출원가 | K36: =VLOOKUP(I36,PL!$A:$S,4,FALSE) -> 0 | L36: =VLOOKUP(I36,PL!$A:$S,18,FALSE) -> 0 | M36: =L36-K36 -> 0 | N36: =IFERROR(M36/K36,0) -> 0
B37: FP01-01-02-0010-03 | C37: 미국제품매입분 | D37: =VLOOKUP(B37,BS!$A:$S,5,FALSE) -> 37776413 | E37: =VLOOKUP(B37,BS!$A:$S,18,FALSE) -> 30676980 | F37: =E37-D37 -> -7099432.8 | G37: =IFERROR(F37/D37,0) -> -0.18793295 | I37: PL02-99 | J37: 기타매출원가 | K37: =VLOOKUP(I37,PL!$A:$S,4,FALSE) -> 0 | L37: =VLOOKUP(I37,PL!$A:$S,18,FALSE) -> 0 | M37: =L37-K37 -> 0 | N37: =IFERROR(M37/K37,0) -> 0
B38: FP01-01-02-0010-04 | C38: 현지매입분 | D38: =VLOOKUP(B38,BS!$A:$S,5,FALSE) -> 81940814 | E38: =VLOOKUP(B38,BS!$A:$S,18,FALSE) -> 82297365 | F38: =E38-D38 -> 356551.26 | G38: =IFERROR(F38/D38,0) -> 0.0043513268 | I38: PL03 | J38: 매출총이익 | K38: =VLOOKUP(I38,PL!$A:$S,4,FALSE) -> 3.9137971e+08 | L38: =VLOOKUP(I38,PL!$A:$S,18,FALSE) -> 1.3991089e+08 | M38: =L38-K38 -> -2.5146882e+08 | N38: =IFERROR(M38/K38,0) -> -0.6425188
B39: FP01-01-02-0010-05 | C39: 기타관계사매입분 | D39: =VLOOKUP(B39,BS!$A:$S,5,FALSE) -> 0 | E39: =VLOOKUP(B39,BS!$A:$S,18,FALSE) -> 0 | F39: =E39-D39 -> 0 | G39: =IFERROR(F39/D39,0) -> 0 | I39: PL04 | J39: 판매비와 관리비 | K39: =VLOOKUP(I39,PL!$A:$S,4,FALSE) -> 5.3813007e+08 | L39: =VLOOKUP(I39,PL!$A:$S,18,FALSE) -> 4.1845286e+08 | M39: =L39-K39 -> -1.196772e+08 | N39: =IFERROR(M39/K39,0) -> -0.22239457
B40: FP01-01-02-0020 | C40: 상품충당금 | D40: =VLOOKUP(B40,BS!$A:$S,5,FALSE) -> -3.1293419e+08 | E40: =VLOOKUP(B40,BS!$A:$S,18,FALSE) -> -3.3371923e+08 | F40: =E40-D40 -> -20785044 | G40: =IFERROR(F40/D40,0) -> 0.066419856 | I40: PL04-00-0010 | J40: 급여 | K40: =VLOOKUP(I40,PL!$A:$S,4,FALSE) -> 2.5966846e+08 | L40: =VLOOKUP(I40,PL!$A:$S,18,FALSE) -> 1.9242924e+08 | M40: =L40-K40 -> -67239220 | N40: =IFERROR(M40/K40,0) -> -0.25894258
...

Sheet BS
A1: 연결계정 | B1: 연결계정명 | C1: 전년동기(월) | D1: 전년동기(누적) | E1: 전년말 | F1: 1월 | G1: 2월 | H1: 3월 | I1: 4월 | J1: 5월 | K1: 6월 | L1: 7월 | M1: 8월 | N1: 9월 | O1: 10월 | P1: 11월 | Q1: 12월 | R1: 회계연월당기 | S1: 증감(회계연월당기-전년말) | T1: 실계정정구분
A2: FP01 | B2: 자산 | C2: -2.4537553e+08 | D2: 4.264932e+09 | E2: 2.8792115e+09 | F2: -2.434442e+08 | G2: -43115788 | H2: -98468299 | I2: 0 | J2: 0 | K2: 0 | L2: 0 | M2: 0 | N2: 0 | O2: 0 | P2: 0 | Q2: 0 | R2: 2.4941833e+09 | S2: -3.8502829e+08 | T2: 2
A3: FP01-01 | B3: 유동자산 | C3: -2.425854e+08 | D3: 4.0216706e+09 | E3: 2.65277e+09 | F3: -2.4034163e+08 | G3: -38623233 | H3: -90755000 | I3: 0 | J3: 0 | K3: 0 | L3: 0 | M3: 0 | N3: 0 | O3: 0 | P3: 0 | Q3: 0 | R3: 2.2830502e+09 | S3: -3.6971986e+08 | T3: 2
A4: FP01-01-01 | B4: 당좌자산 | C4: -90156755 | D4: 2.3010676e+09 | E4: 1.5162714e+09 | F4: -97337323 | G4: -1.3883664e+08 | H4: -1.0630491e+08 | I4: 0 | J4: 0 | K4: 0 | L4: 0 | M4: 0 | N4: 0 | O4: 0 | P4: 0 | Q4: 0 | R4: 1.1737925e+09 | S4: -3.4247887e+08 | T4: 2
A5: FP01-01-01-0010 | B5: 현금및현금성자산 | C5: -1.4577985e+08 | D5: 2.1036494e+08 | E5: 6.0413375e+08 | F5: -9089971.3 | G5: -49303850 | H5: -66584889 | I5: 0 | J5: 0 | K5: 0 | L5: 0 | M5: 0 | N5: 0 | O5: 0 | P5: 0 | Q5: 0 | R5: 4.7915504e+08 | S5: -1.2497871e+08 | T5: 1
A6: FP01-01-01-0020 | B6: 국고보조금(현금) | C6: 0 | D6: 0 | E6: 0 | F6: 0 | G6: 0 | H6: 0 | I6: 0 | J6: 0 | K6: 0 | L6: 0 | M6: 0 | N6: 0 | O6: 0 | P6: 0 | Q6: 0 | R6: 0 | S6: 0 | T6: 1
A7: FP01-01-01-0030 | B7: 단기금융상품 | C7: 0 | D7: 0 | E7: 0 | F7: 0 | G7: 0 | H7: 0 | I7: 0 | J7: 0 | K7: 0 | L7: 0 | M7: 0 | N7: 0 | O7: 0 | P7: 0 | Q7: 0 | R7: 0 | S7: 0 | T7: 1
A8: FP01-01-01-0040 | B8: 단기매매증권 | C8: 0 | D8: 0 | E8: 0 | F8: 0 | G8: 0 | H8: 0 | I8: 0 | J8: 0 | K8: 0 | L8: 0 | M8: 0 | N8: 0 | O8: 0 | P8: 0 | Q8: 0 | R8: 0 | S8: 0 | T8: 1
A9: FP01-01-01-0050 | B9: 만기보유증권 | C9: 0 | D9: 0 | E9: 0 | F9: 0 | G9: 0 | H9: 0 | I9: 0 | J9: 0 | K9: 0 | L9: 0 | M9: 0 | N9: 0 | O9: 0 | P9: 0 | Q9: 0 | R9: 0 | S9: 0 | T9: 1
A10: FP01-01-01-0060 | B10: 매도가능증권 | C10: 0 | D10: 0 | E10: 0 | F10: 0 | G10: 0 | H10: 0 | I10: 0 | J10: 0 | K10: 0 | L10: 0 | M10: 0 | N10: 0 | O10: 0 | P10: 0 | Q10: 0 | R10: 0 | S10: 0 | T10: 1
A11: FP01-01-01-0070 | B11: 매출채권 | C11: -42993393 | D11: 1.4477491e+09 | E11: 7.1296815e+08 | F11: -51756791 | G11: -51958222 | H11: -48997643 | I11: 0 | J11: 0 | K11: 0 | L11: 0 | M11: 0 | N11: 0 | O11: 0 | P11: 0 | Q11: 0 | R11: 5.6025549e+08 | S11: -1.5271266e+08 | T11: 1
A12: FP01-01-01-0080 | B12: 대손충당금(매출채권) | C12: -83520406 | D12: -1.1028842e+08 | E12: -1.8260338e+08 | F12: -36214593 | G12: -62705671 | H12: 11325801 | I12: 0 | J12: 0 | K12: 0 | L12: 0 | M12: 0 | N12: 0 | O12: 0 | P12: 0 | Q12: 0 | R12: -2.7019784e+08 | S12: -87594463 | T12: 1
A13: FP01-01-01-0090 | B13: 현재가치할인차금(단기) | C13: 0 | D13: 0 | E13: 0 | F13: 0 | G13: 0 | H13: 0 | I13: 0 | J13: 0 | K13: 0 | L13: 0 | M13: 0 | N13: 0 | O13: 0 | P13: 0 | Q13: 0 | R13: 0 | S13: 0 | T13: 1
... A81: FP01-02-02-0151 | B81: 국고보조금(공구와기구) | C81: 0 | D81: 0 | E81: 0 | F81: 0 | G81: 0 | H81: 0 | I81: 0 | J81: 0 | K81: 0 | L81: 0 | M81: 0 | N81: 0 | O81: 0 | P81: 0 | Q81: 0 | R81: 0 | S81: 0 | T81: 1
A82: FP01-02-02-0160 | B82: 집기비품 | C82: 0 | D82: 1.216283e+08 | E82: 1.2177752e+08 | F82: 0 | G82: 147200 | H82: -19056966 | I82: 0 | J82: 0 | K82: 0 | L82: 0 | M82: 0 | N82: 0 | O82: 0 | P82: 0 | Q82: 0 | R82: 1.0286775e+08 | S82: -18909766 | T82: 1 | V82: PL | W82: BS | X82: 차액 | Y82: 처분이익 | Z82: 처분손실
A83: FP01-02-02-0170 | B83: 감가상각충당금(집기비품) | C83: -1987229 | D83: -52736372 | E83: -68170204 | F83: -1908350.8 | G83: -1896400.5 | H83: 13537893 | I83: 0 | J83: 0 | K83: 0 | L83: 0 | M83: 0 | N83: 0 | O83: 0 | P83: 0 | Q83: 0 | R83: -58437062 | S83: 9733141.7 | T83: 1 | U83: 유형감가상각비 | V83: =+PL!R56 -> 11359540 | W83: =+S70+S73+S77+S79+S83+S86 -> 6012777.9 | X83: =+V83+W83 -> 17372318 | Y83: =+PL!R92 -> 0 | Z83: =+PL!R126 -> 3699702.5 | AA83: =+X83-Z83 -> 13672615 | AB83: =+X83+Z83 -> 21072020
A84: FP01-02-02-0180 | B84: 손상차손누계액(집기비품) | C84: 0 | D84: 0 | E84: 0 | F84: 0 | G84: 0 | H84: 0 | I84: 0 | J84: 0 | K84: 0 | L84: 0 | M84: 0 | N84: 0 | O84: 0 | P84: 0 | Q84: 0 | R84: 0 | S84: 0 | T84: 1 | U84: 무형감가상각비 | V84: =+PL!R58 -> 66367.77 | W84: =+S104 -> -66367.77 | X84: =+V84+W84 -> 0 | Y84: =+PL!R95 -> 0 | Z84: =+PL!R129 -> 0
A85: FP01-02-02-0190 | B85: 시설장치 | C85: 0 | D85: 0 | E85: 0 | F85: 0 | G85: 0 | H85: 0 | I85: 0 | J85: 0 | K85: 0 | L85: 0 | M85: 0 | N85: 0 | O85: 0 | P85: 0 | Q85: 0 | R85: 0 | S85: 0 | T85: 1 | U85: 리스감가상각비 | V85: =+PL!R57 -> 0 | W85: =S95 -> 0 | X85: =+V85+W85 -> 0 | Y85: =+PL!R94 -> 0 | Z85: =+PL!R128 -> 0
A86: FP01-02-02-0200 | B86: 감가상각충당금(시설장치) | C86: 0 | D86: 0 | E86: 0 | F86: 0 | G86: 0 | H86: 0 | I86: 0 | J86: 0 | K86: 0 | L86: 0 | M86: 0 | N86: 0 | O86: 0 | P86: 0 | Q86: 0 | R86: 0 | S86: 0 | T86: 1
A87: FP01-02-02-0210 | B87: 손상차손누계액(시설장치) | C87: 0 | D87: 0 | E87: 0 | F87: 0 | G87: 0 | H87: 0 | I87: 0 | J87: 0 | K87: 0 | L87: 0 | M87: 0 | N87: 0 | O87: 0 | P87: 0 | Q87: 0 | R87: 0 | S87: 0 | T87: 1
A88: FP01-02-02-0220 | B88: 국고보조금(시설장치) | C88: 0 | D88: 0 | E88: 0 | F88: 0 | G88: 0 | H88: 0 | I88: 0 | J88: 0 | K88: 0 | L88: 0 | M88: 0 | N88: 0 | O88: 0 | P88: 0 | Q88: 0 | R88: 0 | S88: 0 | T88: 1
A89: FP01-02-02-0230 | B89: 금형 | C89: 0 | D89: 0 | E89: 0 | F89: 0 | G89: 0 | H89: 0 | I89: 0 | J89: 0 | K89: 0 | L89: 0 | M89: 0 | N89: 0 | O89: 0 | P89: 0 | Q89: 0 | R89: 0 | S89: 0 | T89: 1
A90: FP01-02-02-0240 | B90: 감가상각충당금(금형) | C90: 0 | D90: 0 | E90: 0 | F90: 0 | G90: 0 | H90: 0 | I90: 0 | J90: 0 | K90: 0 | L90: 0 | M90: 0 | N90: 0 | O90: 0 | P90: 0 | Q90: 0 | R90: 0 | S90: 0 | T90: 1
A91: FP01-02-02-0250 | B91: 손상차손누계액(금형) | C91: 0 | D91: 0 | E91: 0 | F91: 0 | G91: 0 | H91: 0 | I91: 0 | J91: 0 | K91: 0 | L91: 0 | M91: 0 | N91: 0 | O91: 0 | P91: 0 | Q91: 0 | R91: 0 | S91: 0 | T91: 1
A92: FP01-02-02-0260 | B92: 렌탈자산 | C92: 0 | D92: 0 | E92: 0 | F92: 0 | G92: 0 | H92: 0 | I92: 0 | J92: 0 | K92: 0 | L92: 0 | M92: 0 | N92: 0 | O92: 0 | P92: 0 | Q92: 0 | R92: 0 | S92: 0 | T92: 1
A93: FP01-02-02-0270 | B93: 감가상각충당금(렌탈자산) | C93: 0 | D93: 0 | E93: 0 | F93: 0 | G93: 0 | H93: 0 | I93: 0 | J93: 0 | K93: 0 | L93: 0 | M93: 0 | N93: 0 | O93: 0 | P93: 0 | Q93: 0 | R93: 0 | S93: 0 | T93: 1
A94: FP01-02-02-0280 | B94: 사용권자산 | C94: 0 | D94: 0 | E94: 0 | F94: 0 | G94: 0 | H94: 0 | I94: 0 | J94: 0 | K94: 0 | L94: 0 | M94: 0 | N94: 0 | O94: 0 | P94: 0 | Q94: 0 | R94: 0 | S94: 0 | T94: 1
A95: FP01-02-02-0290 | B95: 감가상각충당금(사용권자산) | C95: 0 | D95: 0 | E95: 0 | F95: 0 | G95: 0 | H95: 0 | I95: 0 | J95: 0 | K95: 0 | L95: 0 | M95: 0 | N95: 0 | O95: 0 | P95: 0 | Q95: 0 | R95: 0 | S95: 0 | T95: 1
A96: FP01-02-02-0300 | B96: 건설중인자산 | C96: 0 | D96: 0 | E96: 0 | F96: 0 | G96: 0 | H96: 0 | I96: 0 | J96: 0 | K96: 0 | L96: 0 | M96: 0 | N96: 0 | O96: 0 | P96: 0 | Q96: 0 | R96: 0 | S96: 0 | T96: 1
A97: FP01-02-02-0310 | B97: 국고보조금(건설중인자산) | C97: 0 | D97: 0 | E97: 0 | F97: 0 | G97: 0 | H97: 0 | I97: 0 | J97: 0 | K97: 0 | L97: 0 | M97: 0 | N97: 0 | O97: 0 | P97: 0 | Q97: 0 | R97: 0 | S97: 0 | T97: 1
... A204: FP10 | B204: 부채와 자본총계 | C204: -2.4537553e+08 | D204: 4.264932e+09 | E204: 2.8792115e+09 | F204: -2.434442e+08 | G204: -43115788 | H204: -98468299 | I204: 0 | J204: 0 | K204: 0 | L204: 0 | M204: 0 | N204: 0 | O204: 0 | P204: 0 | Q204: 0 | R204: 2.4941833e+09 | S204: -3.8502829e+08 | T204: 2

Sheet PL
A1: 연결계정 | B1: 연결계정명 | C1: 전년동기(월) | D1: 전년동기(누적) | E1: 전년말 | F1: 1월 | G1: 2월 | H1: 3월 | I1: 4월 | J1: 5월 | K1: 6월 | L1: 7월 | M1: 8월 | N1: 9월 | O1: 10월 | P1: 11월 | Q1: 12월 | R1: 회계연월당기 | S1: 증감(회계연월당기-전년동기누적) | T1: 실계정정구분
A2: PL01 | B2: 매출액 | C2: 4.1793254e+08 | D2: 1.431649e+09 | E2: 3.9511087e+09 | F2: 2.3546103e+08 | G2: 1.4588191e+08 | H2: 1.5976989e+08 | I2: 0 | J2: 0 | K2: 0 | L2: 0 | M2: 0 | N2: 0 | O2: 0 | P2: 0 | Q2: 0 | R2: 5.4111283e+08 | S2: -8.9053612e+08 | T2: 2
A3: PL01-01 | B3: 상품매출액 | C3: 4.1793252e+08 | D3: 1.4309649e+09 | E3: 3.9434622e+09 | F3: 2.3546103e+08 | G3: 1.4588191e+08 | H3: 1.5751817e+08 | I3: 0 | J3: 0 | K3: 0 | L3: 0 | M3: 0 | N3: 0 | O3: 0 | P3: 0 | Q3: 0 | R3: 5.388611e+08 | S3: -8.9210379e+08 | T3: 2
A4: PL01-01-0010 | B4: 본사상품매출액 | C4: 85470656 | D4: 134957920 | E4: 3.6695101e+08 | F4: 11939353 | G4: 24790709 | H4: 8298747.6 | I4: 0 | J4: 0 | K4: 0 | L4: 0 | M4: 0 | N4: 0 | O4: 0 | P4: 0 | Q4: 0 | R4: 45028810 | S4: -89929110 | T4: 1
A5: PL01-01-0020 | B5: 본사제품매출액 | C5: 3.1924149e+08 | D5: 1.2375628e+09 | E5: 3.2812068e+09 | F5: 2.1392202e+08 | G5: 1.1373953e+08 | H5: 1.4520763e+08 | I5: 0 | J5: 0 | K5: 0 | L5: 0 | M5: 0 | N5: 0 | O5: 0 | P5: 0 | Q5: 0 | R5: 4.7286917e+08 | S5: -7.6469361e+08 | T5: 1
A6: PL01-01-0030 | B6: 미국제품매출액 | C6: 6074591 | D6: 34431650 | E6: 87912096 | F6: 5607110.5 | G6: 5925504 | H6: 3059391.2 | I6: 0 | J6: 0 | K6: 0 | L6: 0 | M6: 0 | N6: 0 | O6: 0 | P6: 0 | Q6: 0 | R6: 14592006 | S6: -19839645 | T6: 1
A7: PL01-01-0040 | B7: 현지매입상품매출액 | C7: 7145788 | D7: 24012532 | E7: 207392256 | F7: 3992544.8 | G7: 1426163.7 | H7: 952401.85 | I7: 0 | J7: 0 | K7: 0 | L7: 0 | M7: 0 | N7: 0 | O7: 0 | P7: 0 | Q7: 0 | R7: 6371110.3 | S7: -17641422 | T7: 1
A8: PL01-01-0050 | B8: 기타관계사제품매출액 | C8: 0 | D8: 0 | E8: 0 | F8: 0 | G8: 0 | H8: 0 | I8: 0 | J8: 0 | K8: 0 | L8: 0 | M8: 0 | N8: 0 | O8: 0 | P8: 0 | Q8: 0 | R8: 0 | S8: 0 | T8: 1
A9: PL01-02 | B9: 제품매출액 | C9: 0 | D9: 0 | E9: 0 | F9: 0 | G9: 0 | H9: 0 | I9: 0 | J9: 0 | K9: 0 | L9: 0 | M9: 0 | N9: 0 | O9: 0 | P9: 0 | Q9: 0 | R9: 0 | S9: 0 | T9: 1
A10: PL01-03 | B10: 반제품매출액 | C10: 0 | D10: 0 | E10: 0 | F10: 0 | G10: 0 | H10: 0 | I10: 0 | J10: 0 | K10: 0 | L10: 0 | M10: 0 | N10: 0 | O10: 0 | P10: 0 | Q10: 0 | R10: 0 | S10: 0 | T10: 1
A11: PL01-04 | B11: 원재료매출액 | C11: 0 | D11: 0 | E11: 0 | F11: 0 | G11: 0 | H11: 0 | I11: 0 | J11: 0 | K11: 0 | L11: 0 | M11: 0 | N11: 0 | O11: 0 | P11: 0 | Q11: 0 | R11: 0 | S11: 0 | T11: 1
A12: PL01-05 | B12: IT매출액 | C12: 0 | D12: 0 | E12: 0 | F12: 0 | G12: 0 | H12: 0 | I12: 0 | J12: 0 | K12: 0 | L12: 0 | M12: 0 | N12: 0 | O12: 0 | P12: 0 | Q12: 0 | R12: 0 | S12: 0 | T12: 1
A13: PL01-06 | B13: AS 용역매출액 | C13: 0 | D13: 0 | E13: 1731000 | F13: 0 | G13: 0 | H13: 0 | I13: 0 | J13: 0 | K13: 0 | L13: 0 | M13: 0 | N13: 0 | O13: 0 | P13: 0 | Q13: 0 | R13: 0 | S13: 0 | T13: 1
... A147: PL10-02 | B147: 비지배주주순이익 | C147: 0 | D147: 0 | E147: 0 | F147: 0 | G147: 0 | H147: 0 | I147: 0 | J147: 0 | K147: 0 | L147: 0 | M147: 0 | N147: 0 | O147: 0 | P147: 0 | Q147: 0 | R147: 0 | S147: 0 | T147: 1
